Workbook

Sheet Start
F1: UB 24 | G1: UB 25 | H1: Period | I1: fd Period | J1: Skatt
B3: Omegapoint Malmö AB (Ink E.Syd) | F3: =+_xlfn.XLOOKUP($B$3,$H$101:$H$119,$D$101:$D$119) -> 45657 | G3: =+_xlfn.XLOOKUP($B$3,$H$101:$H$119,$E$101:$E$119) -> 46022 | H3: =+_xlfn.XLOOKUP($B$3,$H$101:$H$119,$F$101:$F$119) -> 2025-01--2025-12 | I3: =+_xlfn.XLOOKUP($B$3,$H$101:$H$119,$G$101:$G$119) -> 2024-01--2024-12 | J3: =+_xlfn.XLOOKUP($B$3,$H$101:$H$119,$J$101:$J$119) -> 0.206
B5: Upprättad av: Djana Dzaferagic
B8: Rapportpaket ska vara klart senast: | D8: 45721
B12: Checklista:
B14: Nettoomsättning per rörelsegren | D14: Utförd
B15: Revisionsarvode | D15: Utförd
B16: Skatt | D16: Utförd
B17: SLP (ej notuppgift) | D17: Utförd
B18: Lön | D18: Utförd
B19: Operationell leasing del 1 | D19: Utförd
B20: Operationell leasing del 2 | D20: Utförd
B21: Resultatandel | D21: Ej tillämplig
B22: FKUI (Förutbetalda kostnader & upplupna intäkter) | D22: Utförd
B23: UKFI (upplupna kostnader & förutbetalda intäkter) | D23: Utförd
B24: Övriga kortfristiga fordringar | D24: Utförd
B25: Övriga kortfristiga fordringar- upparbetat men ej ej fakturerat | D25: Utförd
... B37: Ställda säkerheter och eventualförpliktelser | D37: Utförd
B39: Förvaltningsberättelse | D39: Utförd | E39: Separat worddokument
B40: Not Väsentliga händelser efter räkenskapsårets slut | D40: Utförd | E40: Separat worddokument
B42: Not Övriga ränteintäkter och liknande resultatposter | E42: Anges ej här, Accountor brukar koppla noten direkt mot resultaträkningen
B43: Not Övriga räntekostnader och liknande resultatposter | E43: Anges ej här, Accountor brukar koppla noten direkt mot resultaträkningen
B44: Not Antal aktier och kvotvärde | E44: Anges ej här. Oförändrad mot fg år
B45: Not Disposition av vinst eller förlust | E45: Anges ej här. Accountor kopplar mot resultaträkningen. Ingen utdelning utgår i dotterbolagen. Resultat balanserar i ny räkning.
B46: Not Bokslutsdispositioner | E46: Anges ej här, Accountor brukar koppla noten direkt mot resultaträkningen (koncernbidraget)
B47: Not Uppgifter om moderföretag | E47: Anges ej här. Oförändrad mot fg år
B48: Not Uppgifter om moderföretag- Inköp och förs ljning inom koncernen | E48: Anges i "kompletterande uppgifter"
B50: Kassaflöde med notuppgifter | E50: Anges i "kompletterande uppgifter"
B51: Eget kapital rullning | E51: Anges i "kompletterande uppgifter"
B52: Resultat och Balans klassificering | E52: Anges i "kompletterande uppgifter"
A100: Skatt | D100: (ange) | E100: (ange) | F100: (ange) | H100: (Ange bolag) | K100: (ange) | L100: (ange)
A101: 0.206 | D101: 45657 | E101: 46022 | F101: 2025-01--2025-12 | G101: 2024-01--2024-12 | H101: AB Omegapoint HoldCo | J101: 0.206 | K101: Finansiell | L101: Utförd
A102: 0.206 | D102: 45657 | E102: 46022 | F102: 2025-01--2025-12 | G102: 2024-01--2024-12 | H102: AB Omegapoint | J102: 0.206 | K102: Operationell | L102: Ej tillämplig
A103: 0.206 | B103: (Bokslutsdisp.) | D103: 45657 | E103: 46022 | F103: 2025-01--2025-12 | G103: 2024-01--2024-12 | H103: Omegapoint Stockholm AB | J103: 0.206 | L103: Ej utförd
A104: 0.206 | B104: Koncernbidrag | D104: 45657 | E104: 46022 | F104: 2025-01--2025-12 | G104: 2024-01--2024-12 | H104: Omegapoint Uppsala AB | J104: 0.206
A105: 0.206 | B105: Koncernbidrag | D105: 45657 | E105: 46022 | F105: 2025-01--2025-12 | G105: 2024-01--2024-12 | H105: Omegapoint Göteborg AB (ink Elicit) | J105: 0.206 | K105: (ange) | L105: (ange)
A106: 0.206 | B106: Koncernbidrag | D106: 45657 | E106: 46022 | F106: 2025-01--2025-12 | G106: 2024-01--2024-12 | H106: Omegapoint Malmö AB (Ink E.Syd) | J106: 0.206 | K106: Bil | L106: Kvar. Ej uppsagd
A107: 0.206 | B107: Koncernbidrag | D107: 45657 | E107: 46022 | F107: 2025-01--2025-12 | G107: 2024-01--2024-12 | H107: Omegapoint Denmark ApS | J107: 0.22 | K107: Cykel | L107: Ej kvar. Uppsagd
A108: 0.206 | B108: Koncernbidrag | D108: 45657 | E108: 46022 | F108: 2025-01--2025-12 | G108: 2024-01--2024-12 | H108: Omegapoint Örebro AB | J108: 0.206 | K108: Maskin/inventarie | L108: Kvar. Men uppsagd
A109: 0.206 | B109: Koncernbidrag | D109: 45657 | E109: 46022 | F109: 2025-01--2025-12 | G109: 2024-01--2024-12 | H109: Basalt AB | J109: 0.206 | K109: Lokal/parkering
...

Sheet Notpaket >

Sheet Nettoomsättning per rörelsegren
A1: Not) Nettoomsättning per rörelsegren och geografisk marknad | C1: =+Start!B3 -> Omegapoint Malmö AB (Ink E.Syd) | E1: =+C1 -> Omegapoint Malmö AB (Ink E.Syd)
C7: =+Start!H3 -> 2025-01--2025-12 | E7: =+Start!I3 -> 2024-01--2024-12
C8: Belopp | E8: Belopp
A10: Nettoomsättning per rörelsegren
A12: Konsulttjänster | B12: (konto 3000-3199) | C12: =121088304.85+2 -> 1.2108831e+08 | E12: 1.2650448e+08
A13: Övrig nettoomsättning | B13: (Konto 3200-3799, exkl 3560, 3681 och 3687) | C13: 2448672.9 | E13: 2879458.6
C14: =SUM(C12:C13) -> 1.2353698e+08 | E14: =SUM(E12:E13) -> 1.2938394e+08
A16: Nettoomsättning per geografisk marknad
A18: Sverige | C18: 115486695 | E18: 1.2572195e+08
A19: Norge | C19: 46000
A20: Danmark | C20: 1310631.5 | E20: 542375
A21: Finland | C21: 2515773.2 | E21: 1144614.9
A22: Tyskland | E22: 125296.78
A23: Kanada | E23: 300000
A24: USA | C24: 296588.76 | E24: 404894.08
A25: Irland
A26: Nederländerna | C26: 1584800.2 | E26: 651529.26
A27: Österrike | C27: 71391.48 | E27: 144050.84
A28: Frankrike | E28: 170031
A29: England | C29: 2173466.4
A30: Belgien | C30: 51633 | E30: 179196.97
C31: =SUM(C18:C30) -> 1.2353698e+08 | E31: =SUM(E18:E30) -> 1.2938394e+08
A34: Check | C34: =+C14-C31 -> 0.21999998 | E34: =+E14-E31 -> -0.44000001

Sheet Revisionsarvode
A1: Not) Arvode och kostnadsersättning till revisorer | B1: =+Start!B3 -> Omegapoint Malmö AB (Ink E.Syd) | D1: =+B1 -> Omegapoint Malmö AB (Ink E.Syd)
B5: =+Start!H3 -> 2025-01--2025-12 | D5: =+Start!I3 -> 2024-01--2024-12
B6: Belopp | D6: Belopp
A8: Revisionsarvode
A9: Cedra Sverige AB | B9: 90000
A10: PWC Sverige AB | D10: 90000
A11: (Annan byrå- ange)
A13: Summa | B13: =SUM(B9:B12) -> 90000 | D13: =SUM(D9:D12) -> 90000
A15: Arvoden för revisionsnära konsulttjänster
A16: =+A9 -> Cedra Sverige AB
A17: PWC Sverige AB
A18: (Annan byrå- ange)
A20: Summa | B20: =SUM(B16:B19) -> 0 | D20: =SUM(D16:D19) -> 0
A22: Arvoden för skattekonsultationer
A23: =+A9 -> Cedra Sverige AB
A24: PWC Sverige AB
A25: (Annan byrå- ange)
A27: Summa | B27: =SUM(B23:B26) -> 0 | D27: =SUM(D23:D26) -> 0
A30: Totala arvoden utförd av den stämmovalda revisorn
A31: =+A9 -> Cedra Sverige AB | B31: =+B9+B16+B23 -> 90000 | D31: =+D9+D16+D23 -> 0
A32: PWC Sverige AB | B32: =+B10+B17+B24 -> 0 | D32: =+D10+D17+D24 -> 90000
A33: (Annan byrå- ange) | B33: =+B11+B18+B25 -> 0 | D33: =+D11+D18+D25 -> 0
B34: =+B12+B19+B26 -> 0 | D34: =+D12+D19+D26 -> 0
A35: Summa | B35: =SUM(B31:B34) -> 90000 | D35: =SUM(D31:D34) -> 90000

Sheet Skatt
B1: Skatt på årets resultat | D1: =+[1]Data!B3 -> Omegapoint Malmö AB (Ink E.Syd)
D7: =+[1]Data!H3 -> 2025-01--2025-12
D8: Belopp (lokal valuta)
A10: 8910 | B10: Aktuell bolagsskatt | D10: =IF(D20<0,0,(D20+D49-D65)*C22) -> 2164030.7
A11: (ange konto) | B11: Uppskjuten skatt (- kostnad, + intäkt)
A12: (ange konto) | B12: Justerad skatt fg år (Om differens mot slutskattebeskedet) (- kostnad, +intäkt)
A13: (ange konto) | B13: Skatt på emmissionkostnader (bokförd mot eget kapital) | D13: =-D51*C22 -> 0
B14: Total skatt i bolagets resultat | D14: =SUM(D10:D13) -> 2164030.7
B16: Beräkning
C18: Procent | D18: Belopp (lokal valuta)
B20: Resultat före skatt (före koncernbidrag) | D20: 2197353.5
L21: Avstämning skattenot
B22: Skatt enligt gällande skattesats | C22: =+[1]Data!J3 -> 0.206
L24: =+D20 -> 2197353.5
B25: Ej avdragsgilla kostnader (anges i +) | L25: =-L24*C22 -> -452654.82 | M25: effektiv skatt | O25: =-L25/L24 -> 0.206
A26: 8423 | B26: Räntekostnad på skattekontot | L26: =+L24+L25 -> 1744698.7
A27: 6072 | B27: Ej avdragsgill representation (extern) | D27: 207487.77
A28: 7632 | B28: Ej avdragsgill representation (intern) | D28: 395171.99 | L28: =+D20 -> 2197353.5
A29: 7635 | B29: Ej avdragsgill personalgåvor | D29: 37670 | L29: =+D14 -> 2164030.7 | M29: Bokad skatt | O29: =-L29/L28 -> -0.98483504
A30: 6982 | B30: Ej avdragsgill föreningsavgift | L30: =+L28+L29 -> 4361384.2
A31: (ange konto RR) | B31: Ej avdragsgill sjukvårdsförsäkring
A32: (ange konto RR) | B32: Ej avdragsgill del av självrisk (sjukvårdsförsäkring) | L32: =+L24 -> 2197353.5
A33: 6992 | B33: Ej avdragsgilla övriga externa kostnader | D33: 712.8 | L33: =-L25 -> 452654.82 | M33: Effektiv skatt
A34: 6993 | B34: Gåvor till föreningar/organisationer | D34: 2096 | H34: =D49*C22 -> 1725740.8 | L34: =IF(D20<0,0,D49*C22) -> 1725740.8 | M34: Ej avdragsgilla kostnader
A35: 7818 | B35: Avskrivning fusionsgoodwill (obs! inkråmsgoodwill är avdragsgill och räknas ej med här) | D35: 7664532.7 | H35: =D65*C22 -> 14364.877 | L35: =IF(D20<0,0,-D65*C22) -> -14364.877 | M35: Ej skattepliktiga intäkter
A36: (ange konto RR) | B36: Nedskrivning aktieandelar | L36: =-D52*C22 -> 0 | M36: Emmissionskostnad
A37: (ange konto RR) | B37: Inköp av skattemässiga uppdrag (tex hjälp med deklaration). | L37: =IF(D20<0,0,-(D59+D60)*C22) -> 0 | M37: Skatt underskott
A38: (ange konto RR) | B38: Böter (ska ej finnas, men om det ligger redovisat- ta med) | L38: =IF(D20<0, -D20*C22, 0) -> 0 | M38: Skatt från ej aktiverat underskott
A39: (ange konto RR) | B39: Återbetalning aktieägartillskott (över resultatet). | L39: =+D12 -> 0 | M39: Justerad skatt fg år
A40: (ange konto RR) | B40: Kapitalförsäkringar (P- försäkringar) | L40: =SUM(L32:L39)-L30 -> 0 | M40: diff
A41: (ange konto RR) | B41: Schanblonränta P-fond (om det finns)
A42: (ange konto RR) | B42: Bokförda avskrivningar på inventarier OM under 3 år (anläggningstillgång)
A43: (ange konto RR) | B43: Bokförda avskrivningar på byggnader och förbättringsutgifter på annans fastighet (endast om den aviker från den skattemässiga avskrivningstiden)
A44: (ange konto RR) | B44: Ej avdragsgill ränta (AB Omegapoint enbart)- Erica tilldelar denna | L44: =+D1 -> Omegapoint Malmö AB (Ink E.Syd) | N44: =+D7 -> 2025-01--2025-12
A45: (ange konto RR) | B45: (vid ej definitiv nedskrivningsindikation)- denna tilldelas av Erica | D45: 67095.63
A46: 6902 | B46: Ej avdragsgilla kostnader OP Koko | D46: 2615.63 | L46: Aktuell skatt | N46: =+D10+D12+D13 -> 2164030.7
A47: (ange konto RR) | B47: (Övrigt) | L47: Uppskjuten skatt | N47: =+D11 -> 0
A48: (ange konto RR) | B48: (Övrigt) | N48: =SUM(N46:N47) -> 2164030.7
D49: =SUM(D26:D48) -> 8377382.5 | L49: Avstämning effektiv skatt
B50: Kostnader över eget kapital (anges i +) | M50: Procent | N50: Belopp
...

Sheet Lön
A1: Not) Anställda, personalkostnader och arvoden till styrelse | B1: Omegapoint Malmö AB (Ink E.Syd) | D1: Omegapoint Malmö AB (Ink E.Syd)
A7: Medeltalet anställda (FTE) | B7: 2025-01--2025-12 | D7: 2024-01--2024-12
B8: Antal | D8: Antal
A9: Kvinnor | B9: 24 | D9: 23.49
A10: Män | B10: 61 | D10: 61.54
A11: Totalt | B11: 85 | D11: 85.03
A14: Redovisning av könsfördelning bland ledande befattningshavare
A17: Styrelsen (headcount årets utgång) | B17: 2025-01--2025-12 | D17: 2024-01--2024-12
B18: Antal | D18: Antal
A19: Kvinnor | B19: 1 | D19: 1
A20: Män | B20: 2 | D20: 2
A21: Totalt | B21: 3 | D21: 3
A22: Andel kvinnor i % | B22: 0.33333333 | D22: 0.33333333
A24: Övriga ledande befattningshavare (headcount årets utgång) | B24: 2025-01--2025-12 | D24: 2024-01--2024-12
B25: Antal | D25: Antal
A26: Kvinnor | B26: 1 | D26: 1
A27: Män | B27: 5 | D27: 5
A28: Totalt | B28: 6 | D28: 6
A29: Andel kvinnor i % | B29: 0.16666667 | D29: 0.16666667
A32: Löner och andra ersättningar samt sociala kostnader, inkl pensionskostnader
B34: 2025-01--2025-12 | D34: 2024-01--2024-12
B35: Belopp | D35: Belopp
A36: Styrelse och VD | B36: 1485486.5 | D36: 1487108
A37: Övriga anställda | B37: 54365262 | D37: 55364340
A38: Summa | B38: 55850748 | D38: 56851448
A39: Sociala kostnader (ink pension) | B39: 24515079 | D39: 24441572
A40: (varav pensionskostnader) 1) | B40: 6812847.5 | D40: 6249782.2
A43: 1) Av bolagets pensionskostnader avser 690 638 kr (fg år 649 577 kr) företagets Styrelse och VD.
A44: Bolagets utestående pensionsförpliktelser till dessa uppgår till 0 (0) kr.
A46: Av de löner och ersättningar som lämnats till övriga anställda avser 4 656 458 kr (4 594 619 kr) andra
A47: ledande befattningshavare än styrelse och VD.
A51: Check
A52: Totala personalkostnader (från RR) | B52: 82412818 | D52: 83236811
A53: Löner och sociala kostnader (ovan) | B53: 80365828 | D53: 81293020
A54: Övriga personalrelaterade kostnader (RR) | B54: 2046990 | D54: 1943790.8
A55: Diff | B55: -0.059999992 | D55: -9.5460564e-09
B57: Medel månadslön | D57: Medel månadslön
B59: 54755.636 | D59: 55717.049
A62: Ledande befattningshavare för 2025
A63: 1. Fredrik Lundbeck
...

Sheet Operationell leasing del 2
A1: Not) Operationell leasing | B1: =+Start!B3 -> Omegapoint Malmö AB (Ink E.Syd)
B7: =+Start!H3 -> 2025-01--2025-12
A8: Koncern | B8: Belopp
A10: Avtalade framtida minimileaseavgifter avseende icke
A11: uppsägningsbara kontrakt förfaller till betalning
A12: Inom ett år | B12: =SUM('Operationell leasing del 1'!V20:V170) -> 5646453.1
A13: Mellan ett och fem år | B13: =SUM('Operationell leasing del 1'!W20:W170) -> 14285066
A14: Senare än fem år | B14: =SUM('Operationell leasing del 1'!X20:X170) -> 0
B15: =SUM(B12:B14) -> 19931519
B18: =+Start!H3 -> 2025-01--2025-12
B20: Belopp | C20: (Ange konton i RR)
A21: Räkenskapsårets kostnadsförda leasingavgifter inklusive lokalhyra | B21: 5923999.8 | C21: 5010, 5012, 5220, 5614, 5615
A22: -Varav lokalhyra | B22: 4602552 | C22: 5010

Sheet Operationell leasing del 1
A1: =+Start!B3 -> Omegapoint Malmö AB (Ink E.Syd) | C1: =+Start!G3 -> 46022
A3: Leasingregister
V4: 12 mån | W4: 60 mån | X4: Efter 60 mån
V12: 46023
R15: Senaste fakturan | S15: (Tidigare)
R17: (Feb)
A18: konto | B18: kontraktstyp | C18: Kategori | D18: Benämning | E18: Kontrakt | F18: Startdatum | G18: Slutdatum | H18: Förlängt | J18: Ange status | K18: Datum vid | M18: Förare | N18: Reg Nr | O18: Restvärde | P18: Inköpspris/ | R18: Leasing/hyra | S18: Leasing/hyra
E19: Nr | F19: (Kontrakt) | G19: (Kontrakt) | H19: Slutdatum | K19: Uppsägning | M19: (Bil och cykel) | P19: Avtalsbelopp | R19: Månadsbelopp | S19: Månadsbelopp
A20: 5615 | B20: Finansiell | C20: Bil | D20: ID.7 Tourer Pro S Edition | E20: 30233990 | F20: 45658 | G20: 46752 | I20: =IF(ISBLANK(K20),IF(ISBLANK(H20),G20,H20),K20) -> 46752 | J20: Kvar. Ej uppsagd | M20: Norlander Peter | N20: WBS15Z | O20: =+P20*50% -> 283068.5 | P20: 566137 | R20: 10528.88 | V20: =IF($V$12>I20,0,((IF(DATEDIF($V$12,I20+1,"M")<13,DATEDIF($V$12,I20+1,"M")*R20,12*R20)))) -> 126346.56 | W20: =IF(V20=0,0,(IF(DATEDIF($V$12,I20+1,"M")<60,DATEDIF($V$12,I20+1,"M")*R20,60*R20)-V20)) -> 126346.56 | X20: =IF(V20=0,0,((IF(DATEDIF($V$12,I20+1,"M")>60,DATEDIF($V$12,I20+1,"M")*R20-V20-W20,0)))) -> 0
A21: 5615 | B21: Finansiell | C21: Bil | D21: Passat SC (nya) eHybrid TSI 204 DSG Business Passat SC (nya) eHybrid TSI 204 DSG Business | E21: 30232977 | F21: 45627 | G21: 46721 | I21: =IF(ISBLANK(K21),IF(ISBLANK(H21),G21,H21),K21) -> 46721 | J21: Kvar. Ej uppsagd | M21: Ceasar Carl-Henrik | N21: LSH37Z | O21: =+P21*50% -> 200196 | P21: 400392 | R21: 7448.63 | V21: =IF($V$12>I21,0,((IF(DATEDIF($V$12,I21+1,"M")<13,DATEDIF($V$12,I21+1,"M")*R21,12*R21)))) -> 89383.56 | W21: =IF(V21=0,0,(IF(DATEDIF($V$12,I21+1,"M")<60,DATEDIF($V$12,I21+1,"M")*R21,60*R21)-V21)) -> 81934.93 | X21: =IF(V21=0,0,((IF(DATEDIF($V$12,I21+1,"M")>60,DATEDIF($V$12,I21+1,"M")*R21-V21-W21,0)))) -> 0
A22: 5615 | B22: Finansiell | C22: Bil | D22: BMW, iX3 M Sport Charged LCI | E22: 30235444 | F22: 45566 | G22: 46660 | I22: =IF(ISBLANK(K22),IF(ISBLANK(H22),G22,H22),K22) -> 46660 | J22: Kvar. Ej uppsagd | M22: Rolfson Tobias | N22: KPN09B | O22: =+P22*50% -> 311272 | P22: 622544 | R22: 11593.13 | V22: =IF($V$12>I22,0,((IF(DATEDIF($V$12,I22+1,"M")<13,DATEDIF($V$12,I22+1,"M")*R22,12*R22)))) -> 139117.56 | W22: =IF(V22=0,0,(IF(DATEDIF($V$12,I22+1,"M")<60,DATEDIF($V$12,I22+1,"M")*R22,60*R22)-V22)) -> 104338.17 | X22: =IF(V22=0,0,((IF(DATEDIF($V$12,I22+1,"M")>60,DATEDIF($V$12,I22+1,"M")*R22-V22-W22,0)))) -> 0
A23: 5615 | B23: Finansiell | C23: Bil | D23: KIA EV9 GT Line AWD 2024 | E23: 30233990 | F23: 45505 | G23: 46599 | I23: =IF(ISBLANK(K23),IF(ISBLANK(H23),G23,H23),K23) -> 46599 | J23: Kvar. Ej uppsagd | M23: Wikbrand, Kim | N23: SPW01W | O23: =+P23*50% -> 346179.5 | P23: 692359 | R23: 12910.5 | V23: =IF($V$12>I23,0,((IF(DATEDIF($V$12,I23+1,"M")<13,DATEDIF($V$12,I23+1,"M")*R23,12*R23)))) -> 154926 | W23: =IF(V23=0,0,(IF(DATEDIF($V$12,I23+1,"M")<60,DATEDIF($V$12,I23+1,"M")*R23,60*R23)-V23)) -> 90373.5 | X23: =IF(V23=0,0,((IF(DATEDIF($V$12,I23+1,"M")>60,DATEDIF($V$12,I23+1,"M")*R23-V23-W23,0)))) -> 0
A24: 5615 | B24: Finansiell | C24: Bil | D24: KIA Sorento 1.6 T-GDi Plug-In Hybrid AWD AUT Advance Plus 7-sits | E24: 30241074 | F24: 45748 | G24: 46843 | I24: =IF(ISBLANK(K24),IF(ISBLANK(H24),G24,H24),K24) -> 46843 | J24: Kvar. Ej uppsagd | M24: Gustafsson Mats | N24: JKH17B | O24: =+P24*50% -> 262761 | P24: 525522 | R24: 9766.13 | V24: =IF($V$12>I24,0,((IF(DATEDIF($V$12,I24+1,"M")<13,DATEDIF($V$12,I24+1,"M")*R24,12*R24)))) -> 117193.56 | W24: =IF(V24=0,0,(IF(DATEDIF($V$12,I24+1,"M")<60,DATEDIF($V$12,I24+1,"M")*R24,60*R24)-V24)) -> 146491.95 | X24: =IF(V24=0,0,((IF(DATEDIF($V$12,I24+1,"M")>60,DATEDIF($V$12,I24+1,"M")*R24-V24-W24,0)))) -> 0
A25: 5615 | B25: Finansiell | C25: Bil | D25: Tesla Model Y Performance fyrhjulsdrift | E25: 50555868 | F25: 45105 | G25: 46203 | I25: =IF(ISBLANK(K25),IF(ISBLANK(H25),G25,H25),K25) -> 46203 | J25: Kvar. Ej uppsagd | M25: Lundbeck, Fredrik | N25: BEK28W | O25: =+P25*50% -> 315748 | P25: 631496 | R25: 11618.48 | V25: =IF($V$12>I25,0,((IF(DATEDIF($V$12,I25+1,"M")<13,DATEDIF($V$12,I25+1,"M")*R25,12*R25)))) -> 69710.88 | W25: =IF(V25=0,0,(IF(DATEDIF($V$12,I25+1,"M")<60,DATEDIF($V$12,I25+1,"M")*R25,60*R25)-V25)) -> 0 | X25: =IF(V25=0,0,((IF(DATEDIF($V$12,I25+1,"M")>60,DATEDIF($V$12,I25+1,"M")*R25-V25-W25,0)))) -> 0
A26: 5615 | B26: Finansiell | C26: Bil | D26: VOLVO EC40, 2024 | E26: 30245415 | F26: 45870 | G26: 46965 | I26: =IF(ISBLANK(K26),IF(ISBLANK(H26),G26,H26),K26) -> 46965 | J26: Kvar. Ej uppsagd | M26: Johnson, Jenny | N26: EBR03G | O26: =+P26*50% -> 226170 | P26: 452340 | R26: 8401.5 | V26: =IF($V$12>I26,0,((IF(DATEDIF($V$12,I26+1,"M")<13,DATEDIF($V$12,I26+1,"M")*R26,12*R26)))) -> 100818 | W26: =IF(V26=0,0,(IF(DATEDIF($V$12,I26+1,"M")<60,DATEDIF($V$12,I26+1,"M")*R26,60*R26)-V26)) -> 159628.5 | X26: =IF(V26=0,0,((IF(DATEDIF($V$12,I26+1,"M")>60,DATEDIF($V$12,I26+1,"M")*R26-V26-W26,0)))) -> 0
A27: 5615 | B27: Finansiell | C27: Bil | D27: VOLVO V60, 2025 | E27: 30245566 | F27: 45901 | G27: 46996 | I27: =IF(ISBLANK(K27),IF(ISBLANK(H27),G27,H27),K27) -> 46996 | J27: Kvar. Ej uppsagd | M27: Lindstein Fredrik | N27: PBR06X | O27: =+P27*50% -> 231406 | P27: 462812 | R27: 8595 | V27: =IF($V$12>I27,0,((IF(DATEDIF($V$12,I27+1,"M")<13,DATEDIF($V$12,I27+1,"M")*R27,12*R27)))) -> 103140 | W27: =IF(V27=0,0,(IF(DATEDIF($V$12,I27+1,"M")<60,DATEDIF($V$12,I27+1,"M")*R27,60*R27)-V27)) -> 171900 | X27: =IF(V27=0,0,((IF(DATEDIF($V$12,I27+1,"M")>60,DATEDIF($V$12,I27+1,"M")*R27-V27-W27,0)))) -> 0
A28: 5615 | B28: Finansiell | C28: Bil | D28: VW ID.7 TOURER, 2024 | E28: 30235108 | F28: 45748 | G28: 46843 | I28: =IF(ISBLANK(K28),IF(ISBLANK(H28),G28,H28),K28) -> 46843 | J28: Kvar. Ej uppsagd | M28: Dennie Ovenberg | N28: EYK61X | O28: =+P28*50% -> 283526 | P28: 567052 | R28: 10537.88 | V28: =IF($V$12>I28,0,((IF(DATEDIF($V$12,I28+1,"M")<13,DATEDIF($V$12,I28+1,"M")*R28,12*R28)))) -> 126454.56 | W28: =IF(V28=0,0,(IF(DATEDIF($V$12,I28+1,"M")<60,DATEDIF($V$12,I28+1,"M")*R28,60*R28)-V28)) -> 158068.2 | X28: =IF(V28=0,0,((IF(DATEDIF($V$12,I28+1,"M")>60,DATEDIF($V$12,I28+1,"M")*R28-V28-W28,0)))) -> 0
A29: 5615 | B29: Finansiell | C29: Bil | D29: MiniCooper SE AII4 | E29: 1906228464 | F29: 43739 | G29: 44834 | I29: =IF(ISBLANK(K29),IF(ISBLANK(H29),G29,H29),K29) -> 45862 | J29: Ej kvar. Uppsagd | K29: 45862 | M29: DIAMIR, Johnson, Jenny | N29: ZHR823 | O29: 143117 | P29: 286000 | R29: 4981 | V29: =IF($V$12>I29,0,((IF(DATEDIF($V$12,I29+1,"M")<13,DATEDIF($V$12,I29+1,"M")*R29,12*R29)))) -> 0 | W29: =IF(V29=0,0,(IF(DATEDIF($V$12,I29+1,"M")<60,DATEDIF($V$12,I29+1,"M")*R29,60*R29)-V29)) -> 0 | X29: =IF(V29=0,0,((IF(DATEDIF($V$12,I29+1,"M")>60,DATEDIF($V$12,I29+1,"M")*R29-V29-W29,0)))) -> 0
A30: 5614 | B30: Finansiell | C30: Cykel | D30: Anders Rundgrens cykel? | I30: =IF(ISBLANK(K30),IF(ISBLANK(H30),G30,H30),K30) -> 0 | J30: Ej kvar. Uppsagd | V30: =IF($V$12>I30,0,((IF(DATEDIF($V$12,I30+1,"M")<13,DATEDIF($V$12,I30+1,"M")*R30,12*R30)))) -> 0 | W30: =IF(V30=0,0,(IF(DATEDIF($V$12,I30+1,"M")<60,DATEDIF($V$12,I30+1,"M")*R30,60*R30)-V30)) -> 0 | X30: =IF(V30=0,0,((IF(DATEDIF($V$12,I30+1,"M")>60,DATEDIF($V$12,I30+1,"M")*R30-V30-W30,0)))) -> 0
A31: 5614 | B31: Finansiell | C31: Cykel | D31: Fredrik Lindsteins cykel? | I31: =IF(ISBLANK(K31),IF(ISBLANK(H31),G31,H31),K31) -> 0 | J31: Ej kvar. Uppsagd | V31: =IF($V$12>I31,0,((IF(DATEDIF($V$12,I31+1,"M")<13,DATEDIF($V$12,I31+1,"M")*R31,12*R31)))) -> 0 | W31: =IF(V31=0,0,(IF(DATEDIF($V$12,I31+1,"M")<60,DATEDIF($V$12,I31+1,"M")*R31,60*R31)-V31)) -> 0 | X31: =IF(V31=0,0,((IF(DATEDIF($V$12,I31+1,"M")>60,DATEDIF($V$12,I31+1,"M")*R31-V31-W31,0)))) -> 0
A32: 5010 | B32: Operationell | C32: Lokal/parkering | D32: Hyra Kalendegatan 26 | E32: 1078-5441-05 | F32: 45078 | G32: 47452 | I32: =IF(ISBLANK(K32),IF(ISBLANK(H32),G32,H32),K32) -> 47452 | J32: Kvar. Ej uppsagd | R32: 376721 | V32: =IF($V$12>I32,0,((IF(DATEDIF($V$12,I32+1,"M")<13,DATEDIF($V$12,I32+1,"M")*R32,12*R32)))) -> 4520652 | W32: =IF(V32=0,0,(IF(DATEDIF($V$12,I32+1,"M")<60,DATEDIF($V$12,I32+1,"M")*R32,60*R32)-V32)) -> 13185235 | X32: =IF(V32=0,0,((IF(DATEDIF($V$12,I32+1,"M")>60,DATEDIF($V$12,I32+1,"M")*R32-V32-W32,0)))) -> 0
A33: 5012 | B33: Operationell | C33: Lokal/parkering | D33: Apcoa Parking - Hans Michelsen 9 | E33: H-900023-000053421 | F33: 44743 | G33: 45747 | H33: 46112 | I33: =IF(ISBLANK(K33),IF(ISBLANK(H33),G33,H33),K33) -> 46112 | J33: Kvar. Ej uppsagd | R33: 3949.08 | V33: =IF($V$12>I33,0,((IF(DATEDIF($V$12,I33+1,"M")<13,DATEDIF($V$12,I33+1,"M")*R33,12*R33)))) -> 11847.24 | W33: =IF(V33=0,0,(IF(DATEDIF($V$12,I33+1,"M")<60,DATEDIF($V$12,I33+1,"M")*R33,60*R33)-V33)) -> 0 | X33: =IF(V33=0,0,((IF(DATEDIF($V$12,I33+1,"M")>60,DATEDIF($V$12,I33+1,"M")*R33-V33-W33,0)))) -> 0
A34: 5012 | B34: Operationell | C34: Lokal/parkering | D34: Malmö kommuns parkerings AB/P-huset Bagers Plats feb - 597002, | E34: 403877 | F34: 45383 | H34: 46112 | I34: =IF(ISBLANK(K34),IF(ISBLANK(H34),G34,H34),K34) -> 46112 | J34: Kvar. Ej uppsagd | R34: 1360 | V34: =IF($V$12>I34,0,((IF(DATEDIF($V$12,I34+1,"M")<13,DATEDIF($V$12,I34+1,"M")*R34,12*R34)))) -> 4080 | W34: =IF(V34=0,0,(IF(DATEDIF($V$12,I34+1,"M")<60,DATEDIF($V$12,I34+1,"M")*R34,60*R34)-V34)) -> 0 | X34: =IF(V34=0,0,((IF(DATEDIF($V$12,I34+1,"M")>60,DATEDIF($V$12,I34+1,"M")*R34-V34-W34,0)))) -> 0
A35: 5012 | B35: Operationell | C35: Lokal/parkering | D35: Malmö kommuns parkerings AB/P-huset Bagers Plats feb - 597002, | E35: 227974 | F35: 42948 | G35: 45688 | H35: 46112 | I35: =IF(ISBLANK(K35),IF(ISBLANK(H35),G35,H35),K35) -> 46112 | J35: Kvar. Ej uppsagd | R35: 1360 | V35: =IF($V$12>I35,0,((IF(DATEDIF($V$12,I35+1,"M")<13,DATEDIF($V$12,I35+1,"M")*R35,12*R35)))) -> 4080 | W35: =IF(V35=0,0,(IF(DATEDIF($V$12,I35+1,"M")<60,DATEDIF($V$12,I35+1,"M")*R35,60*R35)-V35)) -> 0 | X35: =IF(V35=0,0,((IF(DATEDIF($V$12,I35+1,"M")>60,DATEDIF($V$12,I35+1,"M")*R35-V35-W35,0)))) -> 0
A36: 5012 | B36: Operationell | C36: Lokal/parkering | D36: Parkman plats 416 Citygaraget (Balder Spinneriet AB) | E36: 1078-8416-04 | F36: 45048 | G36: 45747 | H36: 46112 | I36: =IF(ISBLANK(K36),IF(ISBLANK(H36),G36,H36),K36) -> 46112 | J36: Kvar. Ej uppsagd | R36: 1884.95 | V36: =IF($V$12>I36,0,((IF(DATEDIF($V$12,I36+1,"M")<13,DATEDIF($V$12,I36+1,"M")*R36,12*R36)))) -> 5654.85 | W36: =IF(V36=0,0,(IF(DATEDIF($V$12,I36+1,"M")<60,DATEDIF($V$12,I36+1,"M")*R36,60*R36)-V36)) -> 0 | X36: =IF(V36=0,0,((IF(DATEDIF($V$12,I36+1,"M")>60,DATEDIF($V$12,I36+1,"M")*R36-V36-W36,0)))) -> 0
A37: 5012 | B37: Operationell | C37: Lokal/parkering | D37: Parkman Plats 443 (Balder Spinneriet AB) Citygaraget | E37: 1078-8443-05 | F37: 45048 | G37: 45747 | H37: 46112 | I37: =IF(ISBLANK(K37),IF(ISBLANK(H37),G37,H37),K37) -> 46112 | J37: Ej kvar. Uppsagd | R37: 1639.56 | V37: =IF($V$12>I37,0,((IF(DATEDIF($V$12,I37+1,"M")<13,DATEDIF($V$12,I37+1,"M")*R37,12*R37)))) -> 4918.68 | W37: =IF(V37=0,0,(IF(DATEDIF($V$12,I37+1,"M")<60,DATEDIF($V$12,I37+1,"M")*R37,60*R37)-V37)) -> 0 | X37: =IF(V37=0,0,((IF(DATEDIF($V$12,I37+1,"M")>60,DATEDIF($V$12,I37+1,"M")*R37-V37-W37,0)))) -> 0
A38: 5012 | B38: Operationell | C38: Lokal/parkering | D38: Parkman Plats 446 (Balder Spinneriet AB) Citygaraget | E38: 1078-8446-05 | F38: 45048 | G38: 45747 | H38: 46112 | I38: =IF(ISBLANK(K38),IF(ISBLANK(H38),G38,H38),K38) -> 46112 | J38: Kvar. Ej uppsagd | R38: 1639.56 | V38: =IF($V$12>I38,0,((IF(DATEDIF($V$12,I38+1,"M")<13,DATEDIF($V$12,I38+1,"M")*R38,12*R38)))) -> 4918.68 | W38: =IF(V38=0,0,(IF(DATEDIF($V$12,I38+1,"M")<60,DATEDIF($V$12,I38+1,"M")*R38,60*R38)-V38)) -> 0 | X38: =IF(V38=0,0,((IF(DATEDIF($V$12,I38+1,"M")>60,DATEDIF($V$12,I38+1,"M")*R38-V38-W38,0)))) -> 0
A39: 5012 | B39: Operationell | C39: Lokal/parkering | D39: Parkman Plats 449 (Balder Spinneriet AB) Citygaraget | E39: 1078-8449-10 | F39: 45048 | G39: 45747 | H39: 46112 | I39: =IF(ISBLANK(K39),IF(ISBLANK(H39),G39,H39),K39) -> 46112 | J39: Kvar. Ej uppsagd | R39: 1639.56 | V39: =IF($V$12>I39,0,((IF(DATEDIF($V$12,I39+1,"M")<13,DATEDIF($V$12,I39+1,"M")*R39,12*R39)))) -> 4918.68 | W39: =IF(V39=0,0,(IF(DATEDIF($V$12,I39+1,"M")<60,DATEDIF($V$12,I39+1,"M")*R39,60*R39)-V39)) -> 0 | X39: =IF(V39=0,0,((IF(DATEDIF($V$12,I39+1,"M")>60,DATEDIF($V$12,I39+1,"M")*R39-V39-W39,0)))) -> 0
A40: 5012 | B40: Operationell | C40: Lokal/parkering | D40: Aimo Park Petri P-hus, Rundelsg 17-19/ Kattsundsg. 17-19 | E40: 798810 | F40: 44652 | G40: 45688 | H40: 46112 | I40: =IF(ISBLANK(K40),IF(ISBLANK(H40),G40,H40),K40) -> 46112 | J40: Kvar. Ej uppsagd | R40: 1266.4 | V40: =IF($V$12>I40,0,((IF(DATEDIF($V$12,I40+1,"M")<13,DATEDIF($V$12,I40+1,"M")*R40,12*R40)))) -> 3799.2 | W40: =IF(V40=0,0,(IF(DATEDIF($V$12,I40+1,"M")<60,DATEDIF($V$12,I40+1,"M")*R40,60*R40)-V40)) -> 0 | X40: =IF(V40=0,0,((IF(DATEDIF($V$12,I40+1,"M")>60,DATEDIF($V$12,I40+1,"M")*R40-V40-W40,0)))) -> 0
A41: 5220 | B41: Operationell | C41: Maskin/inventarie | D41: Dejong NIO FM, Org. Kyl ink. Escowa, 302503500 | E41: A10466040 | F41: 45717 | G41: 46965 | I41: =IF(ISBLANK(K41),IF(ISBLANK(H41),G41,H41),K41) -> 46965 | J41: Kvar. Ej uppsagd | R41: 3197.34 | V41: =IF($V$12>I41,0,((IF(DATEDIF($V$12,I41+1,"M")<13,DATEDIF($V$12,I41+1,"M")*R41,12*R41)))) -> 38368.08 | W41: =IF(V41=0,0,(IF(DATEDIF($V$12,I41+1,"M")<60,DATEDIF($V$12,I41+1,"M")*R41,60*R41)-V41)) -> 60749.46 | X41: =IF(V41=0,0,((IF(DATEDIF($V$12,I41+1,"M")>60,DATEDIF($V$12,I41+1,"M")*R41-V41-W41,0)))) -> 0
A42: 5220 | B42: Operationell | C42: Maskin/inventarie | D42: 1 Aqua Vattenautomat, 1 Convini Frys, 1 Convini Kyl ,1 Conv | E42: A10341656 | F42: 45474 | G42: 45565 | H42: 46112 | I42: =IF(ISBLANK(K42),IF(ISBLANK(H42),G42,H42),K42) -> 46112 | J42: Kvar. Ej uppsagd | R42: 4685 | V42: =IF($V$12>I42,0,((IF(DATEDIF($V$12,I42+1,"M")<13,DATEDIF($V$12,I42+1,"M")*R42,12*R42)))) -> 14055 | W42: =IF(V42=0,0,(IF(DATEDIF($V$12,I42+1,"M")<60,DATEDIF($V$12,I42+1,"M")*R42,60*R42)-V42)) -> 0 | X42: =IF(V42=0,0,((IF(DATEDIF($V$12,I42+1,"M")>60,DATEDIF($V$12,I42+1,"M")*R42-V42-W42,0)))) -> 0
A43: 5220 | B43: Operationell | C43: Maskin/inventarie | D43: 1 Aqua Vattenautomat | E43: A10352694 | F43: 45474 | G43: 45565 | H43: 46112 | I43: =IF(ISBLANK(K43),IF(ISBLANK(H43),G43,H43),K43) -> 46112 | J43: Kvar. Ej uppsagd | R43: 690 | V43: =IF($V$12>I43,0,((IF(DATEDIF($V$12,I43+1,"M")<13,DATEDIF($V$12,I43+1,"M")*R43,12*R43)))) -> 2070 | W43: =IF(V43=0,0,(IF(DATEDIF($V$12,I43+1,"M")<60,DATEDIF($V$12,I43+1,"M")*R43,60*R43)-V43)) -> 0 | X43: =IF(V43=0,0,((IF(DATEDIF($V$12,I43+1,"M")>60,DATEDIF($V$12,I43+1,"M")*R43-V43-W43,0)))) -> 0
A44: ange konto | B44: (ange) | C44: (ange) | I44: =IF(ISBLANK(K44),IF(ISBLANK(H44),G44,H44),K44) -> 0 | J44: Kvar. Ej uppsagd | V44: =IF($V$12>I44,0,((IF(DATEDIF($V$12,I44+1,"M")<13,DATEDIF($V$12,I44+1,"M")*R44,12*R44)))) -> 0 | W44: =IF(V44=0,0,(IF(DATEDIF($V$12,I44+1,"M")<60,DATEDIF($V$12,I44+1,"M")*R44,60*R44)-V44)) -> 0 | X44: =IF(V44=0,0,((IF(DATEDIF($V$12,I44+1,"M")>60,DATEDIF($V$12,I44+1,"M")*R44-V44-W44,0)))) -> 0
A45: ange konto | B45: (ange) | C45: (ange) | I45: =IF(ISBLANK(K45),IF(ISBLANK(H45),G45,H45),K45) -> 0 | J45: Kvar. Ej uppsagd | V45: =IF($V$12>I45,0,((IF(DATEDIF($V$12,I45+1,"M")<13,DATEDIF($V$12,I45+1,"M")*R45,12*R45)))) -> 0 | W45: =IF(V45=0,0,(IF(DATEDIF($V$12,I45+1,"M")<60,DATEDIF($V$12,I45+1,"M")*R45,60*R45)-V45)) -> 0 | X45: =IF(V45=0,0,((IF(DATEDIF($V$12,I45+1,"M")>60,DATEDIF($V$12,I45+1,"M")*R45-V45-W45,0)))) -> 0
A46: ange konto | B46: (ange) | C46: (ange) | I46: =IF(ISBLANK(K46),IF(ISBLANK(H46),G46,H46),K46) -> 0 | J46: Kvar. Ej uppsagd | V46: =IF($V$12>I46,0,((IF(DATEDIF($V$12,I46+1,"M")<13,DATEDIF($V$12,I46+1,"M")*R46,12*R46)))) -> 0 | W46: =IF(V46=0,0,(IF(DATEDIF($V$12,I46+1,"M")<60,DATEDIF($V$12,I46+1,"M")*R46,60*R46)-V46)) -> 0 | X46: =IF(V46=0,0,((IF(DATEDIF($V$12,I46+1,"M")>60,DATEDIF($V$12,I46+1,"M")*R46-V46-W46,0)))) -> 0
A47: ange konto | B47: (ange) | C47: (ange) | I47: =IF(ISBLANK(K47),IF(ISBLANK(H47),G47,H47),K47) -> 0 | J47: Kvar. Ej uppsagd | V47: =IF($V$12>I47,0,((IF(DATEDIF($V$12,I47+1,"M")<13,DATEDIF($V$12,I47+1,"M")*R47,12*R47)))) -> 0 | W47: =IF(V47=0,0,(IF(DATEDIF($V$12,I47+1,"M")<60,DATEDIF($V$12,I47+1,"M")*R47,60*R47)-V47)) -> 0 | X47: =IF(V47=0,0,((IF(DATEDIF($V$12,I47+1,"M")>60,DATEDIF($V$12,I47+1,"M")*R47-V47-W47,0)))) -> 0
A48: ange konto | B48: (ange) | C48: (ange) | I48: =IF(ISBLANK(K48),IF(ISBLANK(H48),G48,H48),K48) -> 0 | J48: Kvar. Ej uppsagd | V48: =IF($V$12>I48,0,((IF(DATEDIF($V$12,I48+1,"M")<13,DATEDIF($V$12,I48+1,"M")*R48,12*R48)))) -> 0 | W48: =IF(V48=0,0,(IF(DATEDIF($V$12,I48+1,"M")<60,DATEDIF($V$12,I48+1,"M")*R48,60*R48)-V48)) -> 0 | X48: =IF(V48=0,0,((IF(DATEDIF($V$12,I48+1,"M")>60,DATEDIF($V$12,I48+1,"M")*R48-V48-W48,0)))) -> 0
A49: ange konto | B49: (ange) | C49: (ange) | I49: =IF(ISBLANK(K49),IF(ISBLANK(H49),G49,H49),K49) -> 0 | J49: Kvar. Ej uppsagd | V49: =IF($V$12>I49,0,((IF(DATEDIF($V$12,I49+1,"M")<13,DATEDIF($V$12,I49+1,"M")*R49,12*R49)))) -> 0 | W49: =IF(V49=0,0,(IF(DATEDIF($V$12,I49+1,"M")<60,DATEDIF($V$12,I49+1,"M")*R49,60*R49)-V49)) -> 0 | X49: =IF(V49=0,0,((IF(DATEDIF($V$12,I49+1,"M")>60,DATEDIF($V$12,I49+1,"M")*R49-V49-W49,0)))) -> 0
A50: ange konto | B50: (ange) | C50: (ange) | I50: =IF(ISBLANK(K50),IF(ISBLANK(H50),G50,H50),K50) -> 0 | J50: Kvar. Ej uppsagd | V50: =IF($V$12>I50,0,((IF(DATEDIF($V$12,I50+1,"M")<13,DATEDIF($V$12,I50+1,"M")*R50,12*R50)))) -> 0 | W50: =IF(V50=0,0,(IF(DATEDIF($V$12,I50+1,"M")<60,DATEDIF($V$12,I50+1,"M")*R50,60*R50)-V50)) -> 0 | X50: =IF(V50=0,0,((IF(DATEDIF($V$12,I50+1,"M")>60,DATEDIF($V$12,I50+1,"M")*R50-V50-W50,0)))) -> 0
A51: ange konto | B51: (ange) | C51: (ange) | I51: =IF(ISBLANK(K51),IF(ISBLANK(H51),G51,H51),K51) -> 0 | J51: Kvar. Ej uppsagd | V51: =IF($V$12>I51,0,((IF(DATEDIF($V$12,I51+1,"M")<13,DATEDIF($V$12,I51+1,"M")*R51,12*R51)))) -> 0 | W51: =IF(V51=0,0,(IF(DATEDIF($V$12,I51+1,"M")<60,DATEDIF($V$12,I51+1,"M")*R51,60*R51)-V51)) -> 0 | X51: =IF(V51=0,0,((IF(DATEDIF($V$12,I51+1,"M")>60,DATEDIF($V$12,I51+1,"M")*R51-V51-W51,0)))) -> 0
...

Sheet Resultatandel
A1: Not) Resultatandel
A4: Resultat från andelar i koncernföretag | C4: =+Start!B3 -> Omegapoint Malmö AB (Ink E.Syd) | E4: =+C4 -> Omegapoint Malmö AB (Ink E.Syd)
A6: Belopp | C6: =+Start!H3 -> 2025-01--2025-12 | E6: =+Start!I3 -> 2024-01--2024-12
A8: Utdelning
A9: Nedskrivning andelar i koncernbolag
A10: Avyttring andelar i koncernbolag
A11: Övrigt
C13: =SUM(C8:C11) -> 0 | E13: =SUM(E8:E11) -> 0
A15: Resultat från andelar i intresseföretag
A17: Belopp | C17: =+C6 -> 2025-01--2025-12 | E17: =+E6 -> 2024-01--2024-12
A19: Utdelning
A20: Nedskrivning andelar intressebolag
A21: Avyttring andelar intressebolag
A22: Övrigt
C25: =SUM(C19:C23) -> 0 | E25: =SUM(E19:E23) -> 0

Sheet FKUI
A1: Not) Förutbetalda kostnader och upplupna intäkter
C4: =+Start!B3 -> Omegapoint Malmö AB (Ink E.Syd) | F4: =+Start!B3 -> Omegapoint Malmö AB (Ink E.Syd)
A5: Konton i kontoklass 17
C7: =+Start!G3 -> 46022 | F7: =+Start!F3 -> 45657
C8: Belopp | F8: Belopp
A10: Lokalhyra | C10: 1317409.3 | F10: 1522561.2
A11: Försäkringar | C11: 69592.19 | F11: 64196.96
A12: Pensionskostnader | C12: 568831.7 | F12: 549772.27
A13: Leasingavgifter | C13: 12756.03 | F13: 32839.1
A14: Upplupna intäkter
A15: Programvaror, systemkostnader och licenser | F15: 639178.8
A16: Utbildning- och resekostnader | C16: 456117.56
A17: Underkonsultkostnader
A18: Övriga poster | B18: =+C18/C19 -> 0.048096091 | C18: 122511.23 | E18: =+F18/F19 -> 0.033116663 | F18: 96195.42
C19: =SUM(C10:C18) -> 2547218 | F19: =SUM(F10:F18) -> 2904743.8
A21: Totala saldon för konton 17xx | C21: 2547218 | F21: 2904743.8
A23: Diff | C23: =+C21-C19 -> 0 | F23: =+F21-F19 -> 0
A26: Om "övriga poster" överstiger 10% bryt ut och ange post för post nedan
A28: Post | C28: Belopp | F28: Belopp | H28: Post
A46: Summa | C46: =SUM(C30:C44) -> 0 | F46: =SUM(F30:F44) -> 0
A48: Diff | C48: =IF(B18>9.99999%,+C46-C18,0) -> 0 | F48: =IF(E18>9.99999%,+F46-F18,0) -> 0

Sheet UKFI
A1: Not) Upplupna kostnader och förutbetalda intäkter
C4: =+Start!B3 -> Omegapoint Malmö AB (Ink E.Syd) | F4: =+Start!B3 -> Omegapoint Malmö AB (Ink E.Syd)
A5: Konton i kontoklass 29
C7: =+Start!G3 -> 46022 | F7: =+Start!F3 -> 45657
C8: Belopp | F8: Belopp
A10: Upplupen lön, semester- och övertidsersättning | C10: 7635154.5 | F10: 7547694.6
A11: Upplupna sociala avgifter | C11: 2374431.4 | F11: 2371485
A12: Permitteringsstöd
A13: Förutbetalda intäkter | C13: 510197.41 | F13: 388276.65
A14: Upplupna underskonsulter | C14: 32006.44 | F14: 22767.4
A15: Upplupna revision- och rådgivningskostnader | C15: 70000 | F15: 95000
A16: Övriga poster | B16: =+C16/C17 -> 0.011333868 | C16: 121766.04 | E16: =+F16/F17 -> 0.012029645 | F16: 126938.77
C17: =SUM(C10:C16) -> 10743556 | F17: =SUM(F10:F16) -> 10552162
A19: Saldo konto 29xx | C19: 10743556 | F19: 10552162
A21: Diff | C21: =+C19-C17 -> 0 | F21: =+F19-F17 -> 0
A23: Om "övriga poster" överstiger 10% bryt ut post för post nedan
A25: Post | C25: Belopp | F25: Belopp | H25: Post
A44: Summa | C44: =SUM(C27:C42) -> 0 | F44: =SUM(F27:F42) -> 0
A46: Diff | C46: =IF(B16>9.99999%,+C44-C16,0) -> 0 | F46: =IF(E16>9.99999%,+F44-F16,0) -> 0

Sheet Övriga kf fordringar
A1: Not) Övriga kortfristiga fordringar
C4: =+Start!B3 -> Omegapoint Malmö AB (Ink E.Syd) | F4: =+Start!B3 -> Omegapoint Malmö AB (Ink E.Syd)
A5: Konton i kontoklass 16 (och upparbetad, ej fakturerad intäkt från kontoklass 14)
C7: =+Start!G3 -> 46022 | F7: =+Start!F3 -> 45657
C8: Belopp | F8: Belopp
A10: Upparbetad, ej fakturerad intäkt (Flyttat till nästa flik)
A11: Moms- och skattekonto | C11: 311
A12: Fordran anställda | C12: 2336 | F12: 72251
A13: Övriga poster | B13: =+C13/C14 -> 0 | E13: =+F13/F14 -> 0.8605123 | F13: 445723
C14: =SUM(C10:C13) -> 2647 | F14: =SUM(F10:F13) -> 517974
A16: Saldo berörda balanskonton | C16: 2647 | F16: 517974
A18: Diff | C18: =+C16-C14 -> 0 | F18: =+F16-F14 -> 0
A21: Om "övriga poster" överstiger 10% bryt ut post för post nedan
A23: Post | C23: Belopp | F23: Belopp | H23: Post
F25: 445723 | G25: Skattekonto vid fusion 1631 - Elicit Syd
A42: Summa | C42: =SUM(C25:C40) -> 0 | F42: =SUM(F25:F40) -> 445723
A44: Diff | C44: =IF(B13>9.99999%,+C42-C13,0) -> 0 | F44: =IF(E13>9.99999%,+F42-F13,0) -> 0

Sheet Upparbetat men ej fakturerat
A1: Not) Upparbetad men ej fakturerad intäkt
A2: (Övrig kortfristig fordran)
C4: =+Start!B3 -> Omegapoint Malmö AB (Ink E.Syd) | F4: =+Start!B3 -> Omegapoint Malmö AB (Ink E.Syd)
A5: Konton i kontoklass 14
C7: =+Start!G3 -> 46022 | F7: =+Start!F3 -> 45657
C8: Belopp | F8: Belopp
A10: Upparbetad, ej fakturerad intäkt | C10: 19024345 | F10: 15059732
C13: =SUM(C10:C12) -> 19024345 | F13: =SUM(F10:F12) -> 15059732
A15: Saldo berörda balanskonton | C15: 19024345 | F15: 15059732
A17: Diff | C17: =+C15-C13 -> 0 | F17: =+F15-F13 -> 0

Sheet Fastprisuppdrag
A1: Not) Fordran/skuld på beställaren | C1: =+Start!B3 -> Omegapoint Malmö AB (Ink E.Syd) | E1: =+C1 -> Omegapoint Malmö AB (Ink E.Syd)
A2: Uppdrag till fast pris
C7: =+Start!G3 -> 46022 | E7: =+Start!F3 -> 45657
C8: Belopp | E8: Belopp
A10: Upparbetad men ej fakturerad intäkt
A12: Uppdrag till fast pris- Huvudregeln (successiv vinstavräkning)
A13: Upparbetad intäkt på ej avslutat uppdrag (+) | C13: =89157901 -> 89157901 | E13: 41217070
A14: Fakturerade belopp på ej avslutat uppdrag (-) | C14: -70354133 | E14: -26191338
A15: Summa | C15: =SUM(C13:C14) -> 18803768 | E15: =SUM(E13:E14) -> 15025732
A18: Fakturerad men ej upparbetad intäkt
A20: Uppdrag till fast pris- Huvudregeln (Successiv vinstavräkning)
A21: Upparbetad intäkt på ej avslutat uppdrag (-)
A22: Fakturerade belopp på ej avslutat uppdrag (+)
A23: Summa | C23: =SUM(C21:C22) -> 0 | E23: =SUM(E21:E22) -> 0
A26: Uppdrag till fast pris- Alternativregeln (bör ej finnas)
A27: Fakturerade belopp (+)
A28: Av beställaren innehållna belopp (+)
A33: =18837655-24711 -> 18812944
A34: =-C15 -> -18803768
A35: =SUM(A33:A34) -> 9176

Sheet Likvida medel
A1: Not) Likvida medel | C1: =+Start!B3 -> Omegapoint Malmö AB (Ink E.Syd) | E1: =+C1 -> Omegapoint Malmö AB (Ink E.Syd)
A5: Belopp | C5: =+Start!G3 -> 46022 | E5: =+Start!F3 -> 45657
A6: Följande delkomponenter ingår i likvida medel:
A7: Kassamedel
A8: Kortfristig likvid placering
A9: Banktillgodohavande | E9: 1050.44
A10: Tillgodohavanden på koncernkonto | C10: 704582.81 | E10: -2778651.5
C12: =SUM(C7:C10) -> 704582.81 | E12: =SUM(E7:E10) -> -2777601.1
A14: Tillgodohavande på koncernkonto är klassificerad som "Koncernfordring"
A24: Denna not ska kopplas mot raden för kassa/bank, raden för koncernfordran/koncernskuld i årsredovisningens balansräkning samt (för större K3-bolag) kassaflödet.

Sheet Imm. anläggningstillgångar
A1: Not) Immateriella anläggningstillgångar | B1: =+Start!B3 -> Omegapoint Malmö AB (Ink E.Syd)
I4: Nettoredovisning rörelseförvärv
A8: Immateriella anläggningstillgångar | B8: Goodwill (Fusion/inkråm) | C8: Balanserade utgifter för utvecklingsarbete | D8: Övriga immateriella tillgångar | E8: TOTALT | I8: =+B8 -> Goodwill (Fusion/inkråm) | J8: =+C8 -> Balanserade utgifter för utvecklingsarbete | K8: =+D8 -> Övriga immateriella tillgångar
A9: Period | B9: =+Start!G3 -> 46022 | C9: =+B9 -> 46022 | D9: =+B9 -> 46022 | E9: =+D9 -> 46022
A10: Investeringar | B10: Belopp | C10: Belopp | D10: Belopp
A11: Ingående värde (fg ÅR UB) + | B11: 37751278 | C11: 0 | D11: 0 | E11: =SUM(B11:D11) -> 37751278
A12: Rörelseförvärv + | E12: =SUM(B12:D12) -> 0 | I12: =+B12+B21 -> 0 | J12: =+C12+C21 -> 0 | K12: =+D12+D21 -> 0
A13: Årets anskaffning + | E13: =SUM(B13:D13) -> 0
A14: Avyttring och utrangeringar - | E14: =SUM(B14:D14) -> 0
A15: Omklassificering +/- | E15: =SUM(B15:D15) -> 0
A16: Omräkningseffekt (valutaeffekt) +/- | E16: =SUM(B16:D16) -> 0
A17: Utgående värde | B17: =SUM(B11:B16) -> 37751278 | C17: =SUM(C11:C16) -> 0 | D17: =SUM(D11:D16) -> 0
A19: Avskrivningar | B19: Belopp | C19: Belopp | D19: Belopp
A20: Ingående värde (fg ÅR UB) - | B20: -14499893 | C20: 0 | D20: 0 | E20: =SUM(B20:D20) -> -14499893
A21: Rörelseförvärv - | E21: =SUM(B21:D21) -> 0
A22: Årets avskrivning - | B22: -7664532.7 | E22: =SUM(B22:D22) -> -7664532.7
A23: Återförd avskrivningar på avyttringar och utrangeringar + | E23: =SUM(B23:D23) -> 0
A24: Omklassificering +/- | E24: =SUM(B24:D24) -> 0
A25: Omräkningseffekt (valutaeffekt) +/- | E25: =SUM(B25:D25) -> 0
A26: Utgående värde | B26: =SUM(B20:B25) -> -22164425 | C26: =SUM(C20:C25) -> 0 | D26: =SUM(D20:D25) -> 0
A29: Nedskrivning | B29: Belopp | C29: Belopp | D29: Belopp
A30: Ingående värde (fg ÅR UB) - | E30: =SUM(B30:D30) -> 0
A31: Rörelseförvärv - | E31: =SUM(B31:D31) -> 0
A32: Årets nedskrivning - | E32: =SUM(B32:D32) -> 0
A33: Återförd nedskrivning + | E33: =SUM(B33:D33) -> 0
A34: Omklassificering +/- | E34: =SUM(B34:D34) -> 0
A35: Omräkningseffekt (valutaeffekt) +/- | E35: =SUM(B35:D35) -> 0
A36: Utgående värde | B36: =SUM(B30:B35) -> 0 | C36: =SUM(C30:C35) -> 0 | D36: =SUM(D30:D35) -> 0
A38: Restvärde | B38: =+B17+B26+B36 -> 15586852 | C38: =+C17+C26+C36 -> 0 | D38: =+D17+D26+D36 -> 0
A40: Vinst/avyttring | B40: Belopp | C40: Belopp | D40: Belopp
A41: Försäljningspris | E41: =SUM(B41:D41) -> 0
A42: Total försäljning/utrangering | B42: =+B14+B23+B33 -> 0 | C42: =+C14+C23+C33 -> 0 | D42: =+D14+D23+D33 -> 0
A43: Rea resultat | B43: =+B41+B42 -> 0 | C43: =+C41+C42 -> 0 | D43: =+D41+D42 -> 0

Sheet Materiella anläggningstillgånga
A1: Not) Materiella anläggningstillgångar | B1: =+Start!B3 -> Omegapoint Malmö AB (Ink E.Syd)
H4: Nettoredovisning rörelseförvärv
A8: Materiella anläggningstillgångar | B8: Nedslagda utgifter på annans fastighet | C8: Inventarier, verktyg och installationer | D8: Ägd bil/försäljning företagsbil (ej lease) | E8: TOTALT | H8: =+B8 -> Nedslagda utgifter på annans fastighet | I8: =+C8 -> Inventarier, verktyg och installationer
A9: Period | B9: =+Start!G3 -> 46022 | C9: =+B9 -> 46022 | D9: =+C9 -> 46022 | E9: =+B9 -> 46022
A10: Investeringar | B10: Belopp | C10: Belopp | D10: Belopp
A11: Ingående värde (fg ÅR UB) + | B11: 0 | C11: 1821815.9 | E11: =SUM(B11:C11) -> 1821815.9
A12: Rörelseförvärv + | E12: =SUM(B12:C12) -> 0 | H12: =+B12+B21 -> 0 | I12: =+C12+C21 -> 0
A13: Årets anskaffning + | C13: 174420 | E13: =SUM(B13:C13) -> 174420
A14: Avyttring och utrangeringar - | E14: =SUM(B14:C14) -> 0
A15: Omklassificering +/- | E15: =SUM(B15:C15) -> 0
A16: Omräkningseffekt (valutaeffekt) +/- | E16: =SUM(B16:C16) -> 0
A17: Utgående värde | B17: =SUM(B11:B16) -> 0 | C17: =SUM(C11:C16) -> 1996235.9
A19: Avskrivningar | B19: Belopp | C19: Belopp | D19: Belopp
A20: Ingående värde (fg ÅR UB) - | B20: 0 | C20: -668255.45 | E20: =SUM(B20:C20) -> -668255.45
A21: Rörelseförvärv - | E21: =SUM(B21:C21) -> 0
A22: Årets avskrivning - | C22: -391910.03 | E22: =SUM(B22:C22) -> -391910.03
A23: Återförd avskrivningar på avyttringar och utrangeringar + | E23: =SUM(B23:C23) -> 0
A24: Omklassificering +/- | E24: =SUM(B24:C24) -> 0
A25: Omräkningseffekt (valutaeffekt) +/- | E25: =SUM(B25:C25) -> 0
A26: Utgående värde | B26: =SUM(B20:B25) -> 0 | C26: =SUM(C20:C25) -> -1060165.5 | D26: =SUM(D20:D25) -> 0
A29: Nedskrivning | B29: Belopp | C29: Belopp | D29: Belopp
A30: Ingående värde (fg ÅR UB) - | E30: =SUM(B30:C30) -> 0
A31: Rörelseförvärv - | E31: =SUM(B31:C31) -> 0
A32: Årets nedskrivning - | E32: =SUM(B32:C32) -> 0
A33: Omklassificering +/- | E33: =SUM(B33:C33) -> 0
A34: Återförd nedskrivning + | E34: =SUM(B34:C34) -> 0
A35: Omräkningseffekt (valutaeffekt) +/- | E35: =SUM(B35:C35) -> 0
A36: Utgående värde | B36: =SUM(B30:B35) -> 0 | C36: =SUM(C30:C35) -> 0 | D36: =SUM(D30:D35) -> 0
A38: Restvärde | B38: =+B17+B26+B36 -> 0 | C38: =+C17+C26+C36 -> 936070.47 | D38: =+D17+D26+D36 -> 0
A40: Vinst/avyttring | B40: Belopp | C40: Belopp
A41: Försäljningspris | E41: =SUM(B41:C41) -> 0
A42: Total försäljning/utrangering | B42: =+B14+B23 -> 0 | C42: =+C14+C23 -> 0 | D42: =+D14+D23 -> 0 | E42: =SUM(B42:C42) -> 0
A43: Rea resultat | B43: =+B41+B42 -> 0 | C43: =+C41+C42 -> 0 | D43: =+D41+D42 -> 0 | E43: =SUM(B43:C43) -> 0

Sheet Andelar i intressebolag
A1: Not) Andelar i intressebolag | D1: =+Start!B3 -> Omegapoint Malmö AB (Ink E.Syd)
A5: Belopp i SEK | D5: =+Start!G3 -> 46022
A7: Ackumulerat anskaffningsvärde:
A8: - Vid årets början
A9: - Årets andel i intresseföretagens resultat
A10: - Årets utdelning
A11: - Årets avyttring
A12: Redovisat värde vid årets slut | D12: =SUM(D8:D11) -> 0
D14: =+D5 -> 46022
A16: Bolag: | B16: Org nr: | D16: Justerat EK | E16: Andelar (antal) | F16: Redovisat värde i bolaget
D20: Årets resultat | E20: Andelar (%)
A25: Belopp i SEK | D25: =+Start!F3 -> 45657
A27: Ackumulerat anskaffningsvärde:
A28: - Vid årets början
A29: - Årets andel i intresseföretagens resultat
A30: - Årets utdelning
A31: - Årets avyttring
A32: Redovisat värde vid årets slut | D32: =SUM(D28:D31) -> 0
D34: =+D25 -> 45657
A36: Bolag: | B36: Org nr: | D36: Justerat EK | E36: Andelar (antal) | F36: Redovisat värde i bolaget
D40: Årets resultat | E40: Andelar (%)

Sheet Andelar i koncernbolag
A1: Not) Andelar i koncernbolag | J1: Specifikation andelar i koncernföretag
A3: Belopp i SEK | D3: =+Start!G3 -> 46022 | F3: =+Start!F3 -> 45657 | J3: Namn: | K3: Kapitalandel | L3: Antal andelar | M3: Bokfört värde
A5: Ingående anskaffningsvärde:
A6: - Vid årets början | D6: =+F12 -> 2612322 | F6: 6394432
A7: - Förvärv | J7: Omegapoint North America Inc | K7: 100 | L7: 100 | M7: 1803865
A8: - Aktieägartillskott | F8: 217890 | J8: Omegapoint Denmark ApS | K8: 100 | L8: 40000 | M8: 808457
A9: - Avyttring via fusion | F9: -4000000
A10: - Avyttring via försäljning
A12: Redovisat värde vid årets slut | D12: =SUM(D6:D11) -> 2612322 | F12: =SUM(F6:F11) -> 2612322 | M12: =SUM(M7:M11) -> 2612322
M13: =+D12-M12 -> 0 | N13: check
A16: Not) Avyttring av dotterföretag
A19: Text
A24: Belopp i SEK | D24: =+D3 -> 46022 | F24: =+F3 -> 45657
A26: Avyttringens påverkan på balansräkningen:
A28: Materiella anläggningstillgångar | F28: 0
A29: Varulager | F29: 0
A30: Kundfordringar | F30: 0
A31: Likvida medel | F31: 0
A32: Långfristiga skulder | F32: 0
A33: Leverantörsskulder | F33: 0
A34: Erhållen köpeskilling | D34: =SUM(D28:D33) -> 0 | F34: 0
A36: Likvida medel i det avyttrade företaget | F36: 0
A37: Påverkan på koncernens likvida medel | D37: =+D36 | F37: 0

Sheet Långfristiga värdepappersinneha
A1: Not) Långfristiga värdepappersinnehav | C1: =+Start!B3 -> Omegapoint Malmö AB (Ink E.Syd)
A5: Belopp i SEK | C5: =+Start!G3 -> 46022
A7: Ackumulerat anskaffningsvärde:
A8: - Vid årets början | C8: =+C40 -> 1798
A9: - Årets anskaffning genom genom köp och nyteckningar
A10: - Årets anskaffning genom genom ovillkorade aktieägartillskott
A11: - Årets anskaffning genom genom villkorade aktieägartillskott
A12: - Årets avyttring
A13: - Årets nedskrivning
A14: - Årets omföring från andelar i intressebolag
A15: - Årets valutakursdifferenser
A16: Redovisat värde vid årets slut | C16: =SUM(C8:C15) -> 1798
A20: Bolag: | B20: Org nr: | D20: Andelar (antal) | E20: Redovisat värde i bolaget
A21: B3 IT | B21: 559313-8166 | D21: 62 | E21: 1798.9938
D24: Andelar (%)
D25: =+D49 -> 0.124
A29: Belopp i SEK | C29: =+Start!F3 -> 45657
A31: Ackumulerat anskaffningsvärde:
A32: - Vid årets början
A33: - Årets anskaffning genom genom köp och nyteckningar
A34: - Årets anskaffning genom genom ovillkorade aktieägartillskot | C34: 1798
A35: - Årets anskaffning genom genom villkorade aktieägartillskot
A36: - Årets avyttring
A37: - Årets nedskrivning
A38: - Årets omföring från andelar i intressebolag
A39: - Årets valutakursdifferenser
A40: Redovisat värde vid årets slut | C40: =SUM(C32:C39) -> 1798
A44: Bolag: | B44: Org nr: | D44: Andelar (antal) | E44: Redovisat värde i bolaget
A45: B3 IT | B45: 559313-8166 | D45: 62 | E45: 1798.9938
D48: Andelar (%)
D49: 0.124

Sheet Kortfristiga placeringar
A1: Not) Kortfristigt placeringar | D1: =+Start!B3 -> Omegapoint Malmö AB (Ink E.Syd)
A5: Belopp i SEK | D5: =+Start!G3 -> 46022
A7: Tillgång: | D7: Redovisat värde: | E7: Marknadsvärde:
A12: Redovisat värde vid årets slut | D12: =SUM(D8:D11) -> 0 | E12: =SUM(E8:E11) -> 0
D16: =+D5 -> 46022
A18: Bolag: | B18: Org nr: | D18: Andelar (antal)
D22: Andelar (%)
A26: Belopp i SEK | D26: =+Start!F3 -> 45657
A28: Tillgång: | D28: Redovisat värde: | E28: Marknadsvärde:
A33: Redovisat värde vid årets slut | D33: =SUM(D29:D32) -> 0 | E33: =SUM(E29:E32) -> 0
D37: =+D26 -> 45657
A39: Bolag: | B39: Org nr: | D39: Andelar (antal)
D43: Andelar (%)

Sheet Långfristiga fordringar
A1: Not) Långfristiga fordringar | C1: =+Start!B3 -> Omegapoint Malmö AB (Ink E.Syd) | E1: =+C1 -> Omegapoint Malmö AB (Ink E.Syd)
A5: Belopp i SEK | C5: =+Start!G3 -> 46022 | E5: =+Start!F3 -> 45657
A7: Ackumulerat anskaffningsvärde:
A8: - Vid årets början | C8: =+E12 -> 0
A9: - Tillkommande fordringar
A10: - Årets avyttring
A11: - Årets valutakursdifferenser
A12: Redovisat värde vid årets slut | C12: =SUM(C8:C11) -> 0 | E12: =SUM(E8:E11) -> 0

Sheet Långfristiga skulder
A1: Not) Långfristiga skulder | C1: =+Start!B3 -> Omegapoint Malmö AB (Ink E.Syd) | E1: =+C1 -> Omegapoint Malmö AB (Ink E.Syd)
A5: Belopp i SEK | C5: =+Start!G3 -> 46022 | E5: =+Start!F3 -> 45657
A7: Ackumulerat anskaffningsvärde:
A8: - Vid årets början | C8: =+E12 -> 0
A9: - Tillkommande skulder
A10: - Årets avyttring
A11: - Årets valutakursdifferenser
A12: Redovisat värde vid årets slut | C12: =SUM(C8:C11) -> 0 | E12: =SUM(E8:E11) -> 0

Sheet Skulder till kreditinstut
A1: Not) Skulder till kreditinstitut | C1: =+Start!B3 -> Omegapoint Malmö AB (Ink E.Syd) | E1: =+C1 -> Omegapoint Malmö AB (Ink E.Syd)
A5: Belopp i SEK | C5: =+Start!G3 -> 46022 | E5: =+Start!F3 -> 45657
A7: Långfristiga skulder
A8: Banklån
A9: Summa långfristga skulder | C9: =SUM(C7:C8) -> 0 | E9: =SUM(E7:E8) -> 0
A11: Kortfristiga skulder
A12: Checkräkningskredit
A13: Banklån
A14: Summa kortfristiga skulder | C14: =SUM(C12:C13) -> 0 | E14: =SUM(E12:E13) -> 0
A18: Banklån
A19: Förfallotidpunkt, inom ett år från balansdagen
A20: Förfallotidpunkt, 1-5 år från balansdagen
A21: Förfallotidpunkt, senare än fem år från balansdagen
A22: Redovisat värde vid årets slut | C22: =SUM(C19:C21) -> 0 | E22: =SUM(E19:E21) -> 0
A24: Checkkredit
A25: Beviljad kreditlimit
A26: Outnyttjad del
A27: Redovisat värde vid årets slut | C27: =SUM(C25:C26) -> 0 | E27: =SUM(E25:E26) -> 0
A29: Lånekredit (Revolving Credit Facility)
A30: Beviljad kreditlimit
A31: Outnyttjad del
A32: Redovisat värde vid årets slut | C32: =SUM(C30:C31) -> 0 | E32: =SUM(E30:E31) -> 0
C34: =+C12-C27 -> 0 | E34: =+E12-E27 -> 0

Sheet Ställda säkerheter och eventual
A1: Not) Ställda säkerheter och eventualförpliktelser | H1: =+Start!B3 -> Omegapoint Malmö AB (Ink E.Syd) | J1: =+H1 -> Omegapoint Malmö AB (Ink E.Syd)
H5: =+Start!G3 -> 46022 | J5: =+Start!F3 -> 45657
H6: Belopp | J6: Belopp
A8: Ställda säkerheter
A9: Företagsinteckningar | H9: 1500000 | J9: 1500000
A10: Fastighetsinteckningar
A11: Aktier i bolag | J11: 2612322
A12: Övrigt
A14: Summa ställda säkerheter | H14: =SUM(H9:H12) -> 1500000 | J14: =SUM(J9:J12) -> 4112322
A16: Eventualförpliktelser och ansvarsförpliktelser
A18: Hyresgaranti
A19: Garantiförbindelse
A20: Borgen, banklån | H20: 715000000 | J20: 743880000
A21: Övriga ansvarsförpliktelser
A23: Summa eventualförpliktelser | H23: =SUM(H18:H19) -> 0 | J23: =SUM(J18:J19) -> 0
A25: I enlighet med låneavtal mellan Swedbank och AB Omegapoint, 559312-6120, ansvarar varje borgensman solidariskt i enlighet med Aktiebolagslagen 2005:551 varandras åtaganden.
A26: Moderföretagets aktier i dotterföretag är enligt låneavtalet pantsatta som säkerhet.
